<mujoco>
	<body mocap="true" name="robot0:mocap" pos="0 0 0">
		<geom conaffinity="0" contype="0" pos="0 0 0" rgba="0 0.5 0 0.7" size="0.005 0.005 0.005" type="box"></geom>
		<geom conaffinity="0" contype="0" pos="0 0 0" rgba="0 0.5 0 0.1" size="1 0.005 0.005" type="box"></geom>
		<geom conaffinity="0" contype="0" pos="0 0 0" rgba="0 0.5 0 0.1" size="0.005 1 0.001" type="box"></geom>
		<geom conaffinity="0" contype="0" pos="0 0 0" rgba="0 0.5 0 0.1" size="0.005 0.005 1" type="box"></geom>
	</body>
	<body childclass="robot0:fetch" name="robot0:base_link" pos="0.2869 0.2641 0">
		<joint armature="0.0001" axis="1 0 0" damping="1e+11" name="robot0:slide0" pos="0 0 0" type="slide"></joint>
		<joint armature="0.0001" axis="0 1 0" damping="1e+11" name="robot0:slide1" pos="0 0 0" type="slide"></joint>
		<joint armature="0.0001" axis="0 0 1" damping="1e+11" name="robot0:slide2" pos="0 0 0" type="slide"></joint>
		<inertial diaginertia="1.2869 1.2236 0.9868" mass="70.1294" pos="-0.0036 0 0.0014" quat="0.7605 -0.0133 -0.0061 0.6491"></inertial>
		<geom mesh="robot0:base_link" name="robot0:base_link" material="robot0:base_mat" class="robot0:grey"></geom>
		<body name="robot0:torso_lift_link" pos="-0.0869 0 0.3774">
			<inertial diaginertia="0.3365 0.3354 0.0943" mass="10.7796" pos="-0.0013 -0.0009 0.2935" quat="0.9993 -0.0006 0.0336 0.0185"></inertial>
			<joint axis="0 0 1" damping="1e+07" name="robot0:torso_lift_joint" range="0.0386 0.3861" type="slide"></joint>
			<geom mesh="robot0:torso_lift_link" name="robot0:torso_lift_link" material="robot0:torso_mat"></geom>
			<body name="robot0:head_pan_link" pos="0.0531 0 0.603">
				<inertial diaginertia="0.0185 0.0128 0.0095" mass="2.2556" pos="0.0321 0.0161 0.039" quat="0.5148 0.5451 -0.453 0.4823"></inertial>
				<joint axis="0 0 1" name="robot0:head_pan_joint" range="-1.57 1.57"></joint>
				<geom mesh="robot0:head_pan_link" name="robot0:head_pan_link" material="robot0:head_mat" class="robot0:grey"></geom>
				<body name="robot0:head_tilt_link" pos="0.1425 0 0.058">
					<inertial diaginertia="0.0063 0.0059 0.0014" mass="0.9087" pos="0.0081 0.0025 0.0113" quat="0.6458 0.66 -0.274 0.2689"></inertial>
					<joint axis="0 1 0" damping="1000" name="robot0:head_tilt_joint" range="-0.76 1.45" ref="0.06"></joint>
					<geom mesh="robot0:head_tilt_link" name="robot0:head_tilt_link" material="robot0:head_mat" class="robot0:blue"></geom>
					<body name="robot0:head_camera_link" pos="0.055 0 0.0225">
						<inertial diaginertia="0 0 0" mass="0" pos="0.055 0 0.0225"></inertial>
						<body name="robot0:head_camera_rgb_frame" pos="0 0.02 0">
							<inertial diaginertia="0 0 0" mass="0" pos="0 0.02 0"></inertial>
							<body name="robot0:head_camera_rgb_optical_frame" pos="0 0 0" quat="0.5 -0.5 0.5 -0.5">
								<inertial diaginertia="0 0 0" mass="0" pos="0 0 0" quat="0.5 -0.5 0.5 -0.5"></inertial>
								<camera euler="3.1415 0 0" fovy="50" name="head_camera_rgb" pos="0 0 0"></camera>
							</body>
						</body>
						<body name="robot0:head_camera_depth_frame" pos="0 0.045 0">
							<inertial diaginertia="0 0 0" mass="0" pos="0 0.045 0"></inertial>
							<body name="robot0:head_camera_depth_optical_frame" pos="0 0 0" quat="0.5 -0.5 0.5 -0.5">
								<inertial diaginertia="0 0 0" mass="0" pos="0 0 0" quat="0.5 -0.5 0.5 -0.5"></inertial>
							</body>
						</body>
					</body>
				</body>
			</body>
		       <body name="panda_link0" pos="0 0 0">
			    <inertial pos="-0.0291898 -0.000879465 0.0566032" quat="0.00411744 0.564916 0.0132875 0.825031" mass="3.01399" diaginertia="0.0126801 0.0117603 0.00856656" />
			    <geom type="mesh" rgba="1 1 1 1" mesh="link0" />
			    <body name="panda_link1" pos="0 0 0.333">
				<inertial pos="1.1399e-05 -0.0312655 -0.0693733" quat="0.98466 0.174481 -0.000101815 0.000347662" mass="2.77281" diaginertia="0.0164224 0.0153969 0.00546286" />
				<joint name="panda_joint1" pos="0 0 0" axis="0 0 1" limited="true" range="-2.9671 2.9671" />
				<geom type="mesh" rgba="1 1 1 1" mesh="link1" />
				<body name="panda_link2" pos="0 0 0" quat="0.707107 -0.707107 0 0">
				    <inertial pos="-1.31766e-05 -0.0703216 0.0311782" quat="0.57484 0.818266 -6.05764e-05 -6.61626e-05" mass="2.7996" diaginertia="0.016787 0.0157415 0.00553027" />
				    <joint name="panda_joint2" pos="0 0 0" axis="0 0 1" limited="true" range="-1.8326 1.8326" />
				    <geom type="mesh" rgba="1 1 1 1" mesh="link2" />
				    <body name="panda_link3" pos="0 -0.316 0" quat="0.707107 0.707107 0 0">
				        <inertial pos="0.0443483 0.0249283 -0.03813" quat="0.0615263 0.349824 0.234291 0.904956" mass="2.14603" diaginertia="0.00915257 0.00896477 0.00384742" />
				        <joint name="panda_joint3" pos="0 0 0" axis="0 0 1" limited="true" range="-2.9671 2.9671" />
				        <geom type="mesh" rgba="1 1 1 1" mesh="link3" />
				        <body name="panda_link4" pos="0.0825 0 0" quat="0.707107 0.707107 0 0">
				            <inertial pos="-0.0385503 0.0395256 0.0247162" quat="0.813566 0.465041 0.309792 0.160858" mass="2.18807" diaginertia="0.00946899 0.00928491 0.00396694" />
				            <joint name="panda_joint4" pos="0 0 0" axis="0 0 1" limited="true" range="-3.1416 0" />
				            <geom type="mesh" rgba="1 1 1 1" mesh="link4" />
				            <body name="panda_link5" pos="-0.0825 0.384 0" quat="0.707107 -0.707107 0 0">
				                <inertial pos="-6.36776e-05 0.0384124 -0.10997" quat="0.990767 -0.135571 0.000963106 0.000694406" mass="3.19545" diaginertia="0.0278873 0.0268823 0.00569569" />
				                <joint name="panda_joint5" pos="0 0 0" axis="0 0 1" limited="true" range="-2.9671 2.9671" />
				                <geom type="mesh" rgba="1 1 1 1" mesh="link5" />
				                <body name="panda_link6" pos="0 0 0" quat="0.707107 0.707107 0 0">
				                    <inertial pos="0.0510023 0.00693267 0.00616899" quat="-0.0460841 0.754362 0.044494 0.653325" mass="1.35761" diaginertia="0.00412168 0.0033698 0.00213304" />
				                    <joint name="panda_joint6" pos="0 0 0" axis="0 0 1" limited="true" range="-0.0873 3.8223" />
				                    <geom type="mesh" rgba="1 1 1 1" mesh="link6" />
				                    <body name="panda_link7" pos="0.088 0 0" quat="0.707107 0.707107 0 0">
				                        <inertial pos="0.0103614 0.0103596 0.0791078" quat="0.63547 0.278021 -0.670462 0.263369" mass="0.417345" diaginertia="0.000637671 0.000528056 0.000279577" />
				                        <joint name="panda_joint7" pos="0 0 0" axis="0 0 1" limited="true" range="-2.9671 2.9671" />
				                        <geom type="mesh" rgba="1 1 1 1" mesh="link7" />
				                        <body name="panda_link8" pos="0 0 0.107">
				                            <inertial pos="0 0 0.107" mass="0" diaginertia="0 0 0" />
				                            <body name="panda_hand" pos="0 0 0" quat="0.92388 0 0 -0.382683">
				                                <inertial pos="-2.76618e-06 -0.00061547 0.0239295" quat="0.697945 0.716151 -0.000242485 8.47563e-05" mass="0.670782" diaginertia="0.00227632 0.00206087 0.000456542" />
				                                <geom type="mesh" rgba="1 1 1 1" mesh="hand" />
				                                <body childclass="robot0:fetchGripper" name="panda_leftfinger" pos="0 0 0.0584">
				                                    <inertial pos="-2.42335e-05 0.0119585 0.0237816" quat="0.996177 0.0868636 -2.79333e-05 -0.00926642" mass="0.0218754" diaginertia="5.69661e-06 5.56035e-06 1.55183e-06" />
				                                    <joint name="panda_finger_joint1" pos="0 0 0" axis="0 1 0" type="slide" limited="true" range="0 0.04" />
				                                    <geom type="mesh" rgba="1 1 1 1" mesh="finger" />
				                                </body>
				                                <body childclass="robot0:fetchGripper" name="panda_rightfinger" pos="0 0 0.0584">
				                                    <inertial pos="2.42335e-05 -0.0119585 0.0237816" quat="0.00926642 2.79333e-05 0.0868636 0.996177" mass="0.0218754" diaginertia="5.69661e-06 5.56035e-06 1.55183e-06" />
				                                    <joint name="panda_finger_joint2" pos="0 0 0" axis="0 -1 0" type="slide" limited="true" range="0 0.04" />
				                                    <geom quat="0 0 0 1" type="mesh" rgba="1 1 1 1" mesh="finger" />
				                                </body>
								<body name="robot0:gipper_camera_link" pos="0.055 0 0.0225">
									<body name="robot0:gripper_camera_rgb_frame" pos="0 0.02 0">
										<body name="robot0:gripper_camera_rgb_optical_frame" pos="0 0 0" quat="0.5 -0.5 0.5 -0.5">
											<camera euler="3.1415 0 0" fovy="50" name="gripper_camera_rgb" pos="0 0 0"></camera>
										</body>
									</body>
									<body name="robot0:gripper_camera_depth_frame" pos="0 0.045 0">
										<body name="robot0:gripper_camera_depth_optical_frame" pos="0 0 0" quat="0.5 -0.5 0.5 -0.5"></body>
									</body>
								</body>
								<site name="robot0:grip" pos="0.02 0 0" rgba="0 0 0 0" size="0.02 0.02 0.02"></site>
				                            </body>
				                        </body>
				                    </body>
				                </body>
				            </body>
				        </body>
				    </body>
				</body>
	 		   </body>
		      </body>
 		</body>
		<body name="robot0:estop_link" pos="-0.1246 0.2389 0.3113" quat="0.7071 0.7071 0 0">
			<inertial diaginertia="0 0 0" mass="0.002" pos="0.0024 -0.0033 0.0067" quat="0.3774 -0.1814 0.1375 0.8977"></inertial>
			<geom mesh="robot0:estop_link" rgba="0.8 0 0 1" name="robot0:estop_link"></geom>
		</body>
		<body name="robot0:laser_link" pos="0.235 0 0.2878" quat="0 1 0 0">
			<inertial diaginertia="0 0 0" mass="0.0083" pos="-0.0306 0.0007 0.0552" quat="0.5878 0.5378 -0.4578 0.3945"></inertial>
			<geom mesh="robot0:laser_link" rgba="0.7922 0.8196 0.9333 1" name="robot0:laser_link"></geom>
			<camera euler="1.55 -1.55 3.14" fovy="25" name="lidar" pos="0 0 0.02"></camera>
		</body>
		<body name="robot0:torso_fixed_link" pos="-0.0869 0 0.05">
			<inertial diaginertia="0.3865 0.3394 0.1009" mass="13.2775" pos="-0.0722 0.0057 0.2656" quat="0.9995 0.0249 0.0177 0.011"></inertial>
			<geom mesh="robot0:torso_fixed_link" name="robot0:torso_fixed_link" class="robot0:blue"></geom>
		</body>
		<body name="robot0:external_camera_body_0" pos="0 0 0">
			<camera euler="0 0.75 1.57" fovy="43.3" name="external_camera_0" pos="1.3 0 1.2"></camera>
		</body>
	</body>
</mujoco>
